Workbook

Sheet チェックリスト
A1: 生成AI利用ガイドライン チェックリスト
A2: 組織名: ＿＿＿＿＿ 記入者: ＿＿＿＿＿ 記入日: ＿＿＿＿年＿＿月＿＿日
A3: チェック結果 | B3: 項目番号 | C3: 章 | D3: 章タイトル | E3: 節 | F3: 節タイトル | G3: 準拠レベル | H3: チェック項目 | I3: NIST | J3: NIST-GAI | K3: METI | L3: JDLA | M3: IPA | N3: FUJITSU | O3: EU-AIA | P3: 備考 | Q3: 対応状況メモ
B4: 1.1.A | C4: 1 | D4: ガバナンス体制 (GOVERN) | E4: 1.1 | F4: 組織体制・責任 | G4: Required | H4: 生成AI利用に関する最終責任者（経営層）が明確に定められている | I4: ○ | K4: ○
B5: 1.1.B | C5: 1 | D5: ガバナンス体制 (GOVERN) | E5: 1.1 | F5: 組織体制・責任 | G5: Required | H5: AI利用に関する担当部門・担当者が指定されている | I5: ○ | L5: ○
B6: 1.1.C | C6: 1 | D6: ガバナンス体制 (GOVERN) | E6: 1.1 | F6: 組織体制・責任 | G6: Recommended | H6: 部門横断的な推進体制（法務、情報システム、事業部門等）が構築されている | I6: ○ | M6: ○
B7: 1.1.D | C7: 1 | D7: ガバナンス体制 (GOVERN) | E7: 1.1 | F7: 組織体制・責任 | G7: Required | H7: 役割と責任の範囲が文書化されている | I7: ○ | K7: ○
B8: 1.1.E | C8: 1 | D8: ガバナンス体制 (GOVERN) | E8: 1.1 | F8: 組織体制・責任 | G8: Required | H8: インシデント発生時のエスカレーションルートが定められている | I8: ○ | M8: ○
B9: 1.1.F | C9: 1 | D9: ガバナンス体制 (GOVERN) | E9: 1.1 | F9: 組織体制・責任 | G9: Option | H9: 多様な視点を持つチーム構成が考慮されている | I9: ○
B10: 1.2.A | C10: 1 | D10: ガバナンス体制 (GOVERN) | E10: 1.2 | F10: ポリシー・規程 | G10: Required | H10: 生成AI利用の目的・方針が明記されている | I10: ○ | L10: ○
B11: 1.2.B | C11: 1 | D11: ガバナンス体制 (GOVERN) | E11: 1.2 | F11: ポリシー・規程 | G11: Required | H11: ガイドラインの適用範囲（対象者、対象業務、対象ツール）が明確である | L11: ○ | M11: ○
B12: 1.2.C | C12: 1 | D12: ガバナンス体制 (GOVERN) | E12: 1.2 | F12: ポリシー・規程 | G12: Required | H12: 既存の情報セキュリティポリシー、個人情報保護方針との整合性が取れている | I12: ○ | K12: ○
B13: 1.2.D | C13: 1 | D13: ガバナンス体制 (GOVERN) | E13: 1.2 | F13: ポリシー・規程 | G13: Required | H13: 関連する法令・規制要件（個人情報保護法、著作権法等）への言及がある | I13: ○ | L13: ○
B14: 1.2.E | C14: 1 | D14: ガバナンス体制 (GOVERN) | E14: 1.2 | F14: ポリシー・規程 | G14: Recommended | H14: ガイドラインの定期的な見直し・更新の仕組みが定められている | I14: ○ | K14: ○
B15: 1.2.F | C15: 1 | D15: ガバナンス体制 (GOVERN) | E15: 1.2 | F15: ポリシー・規程 | G15: Recommended | H15: リスク許容度が組織として定義されている | I15: ○ | K15: ○
B16: 1.3.A | C16: 1 | D16: ガバナンス体制 (GOVERN) | E16: 1.3 | F16: 教育・研修 | G16: Required | H16: 従業員向けの生成AI利用研修が計画されている | I16: ○ | L16: ○
B17: 1.3.B | C17: 1 | D17: ガバナンス体制 (GOVERN) | E17: 1.3 | F17: 教育・研修 | G17: Recommended | H17: ITリテラシーレベルに応じた教育内容が用意されている | L17: ○ | M17: ○
B18: 1.3.C | C18: 1 | D18: ガバナンス体制 (GOVERN) | E18: 1.3 | F18: 教育・研修 | G18: Required | H18: 新規利用者向けのオンボーディングプロセスがある | I18: ○
B19: 1.3.D | C19: 1 | D19: ガバナンス体制 (GOVERN) | E19: 1.3 | F19: 教育・研修 | G19: Recommended | H19: 継続的な啓発活動（事例共有、注意喚起等）の仕組みがある | I19: ○ | L19: ○
B20: 1.4.A | C20: 1 | D20: ガバナンス体制 (GOVERN) | E20: 1.4 | F20: 監視・監査 | G20: Option | H20: 利用状況のモニタリング方法が定められている | I20: ○ | M20: ○
B21: 1.4.B | C21: 1 | D21: ガバナンス体制 (GOVERN) | E21: 1.4 | F21: 監視・監査 | G21: Option | H21: 定期的な監査・レビューの実施計画がある | I21: ○ | K21: ○
B22: 1.4.C | C22: 1 | D22: ガバナンス体制 (GOVERN) | E22: 1.4 | F22: 監視・監査 | G22: Required | H22: 違反時の対応プロセスが明記されている | L22: ○ | M22: ○
B23: 1.4.D | C23: 1 | D23: ガバナンス体制 (GOVERN) | E23: 1.4 | F23: 監視・監査 | G23: Recommended | H23: AIシステムのインベントリ管理の仕組みがある | I23: ○
B24: 1.4.E | C24: 1 | D24: ガバナンス体制 (GOVERN) | E24: 1.4 | F24: 監視・監査 | G24: Recommended | H24: AIサービスの提供終了・重大変更時の対応方針がある | I24: ○
B25: 2.1.A | C25: 2 | D25: リスクの特定と評価 (MAP) | E25: 2.1 | F25: 利用目的・文脈の明確化 | G25: Required | H25: 生成AIを利用する業務・ユースケースが特定されている | I25: ○ | L25: ○
B26: 2.1.B | C26: 2 | D26: リスクの特定と評価 (MAP) | E26: 2.1 | F26: 利用目的・文脈の明確化 | G26: Required | H26: 各ユースケースにおける期待される効果（便益）が文書化されている | I26: ○ | K26: ○
B27: 2.1.C | C27: 2 | D27: リスクの特定と評価 (MAP) | E27: 2.1 | F27: 利用目的・文脈の明確化 | G27: Required | H27: 想定ユーザーとその利用方法が定義されている | I27: ○ | K27: ○
B28: 2.1.D | C28: 2 | D28: リスクの特定と評価 (MAP) | E28: 2.1 | F28: 利用目的・文脈の明確化 | G28: Required | H28: AIを使用すべきでない業務・場面が明記されている | I28: ○ | L28: ○
B29: 2.1.E | C29: 2 | D29: リスクの特定と評価 (MAP) | E29: 2.1 | F29: 利用目的・文脈の明確化 | G29: Required | H29: ビジネス価値・目的が明確に定義されている | I29: ○
B30: 2.1.F | C30: 2 | D30: リスクの特定と評価 (MAP) | E30: 2.1 | F30: 利用目的・文脈の明確化 | G30: Required | H30: 組織のミッション・目標との整合性が確認されている | I30: ○
B31: 2.2.A | C31: 2 | D31: リスクの特定と評価 (MAP) | E31: 2.2 | F31: リスクの分類と評価 | G31: Required | H31: 情報漏えいリスクの評価がされている | L31: ○ | M31: ○ | N31: ○
B32: 2.2.B | C32: 2 | D32: リスクの特定と評価 (MAP) | E32: 2.2 | F32: リスクの分類と評価 | G32: Required | H32: 著作権・知的財産権侵害リスクの評価がされている | K32: ○ | L32: ○ | N32: ○
B33: 2.2.C | C33: 2 | D33: リスクの特定と評価 (MAP) | E33: 2.2 | F33: リスクの分類と評価 | G33: Required | H33: ハルシネーション（誤情報生成）リスクの評価がされている | J33: ○ | L33: ○ | N33: ○
B34: 2.2.D | C34: 2 | D34: リスクの特定と評価 (MAP) | E34: 2.2 | F34: リスクの分類と評価 | G34: Recommended | H34: バイアス・公平性に関するリスクの評価がされている | I34: ○ | K34: ○ | N34: ○
B35: 2.2.E | C35: 2 | D35: リスクの特定と評価 (MAP) | E35: 2.2 | F35: リスクの分類と評価 | G35: Required | H35: プライバシーリスクの評価がされている | I35: ○ | K35: ○
B36: 2.2.F | C36: 2 | D36: リスクの特定と評価 (MAP) | E36: 2.2 | F36: リスクの分類と評価 | G36: Required | H36: セキュリティリスク（プロンプトインジェクション等）の評価がされている | J36: ○ | M36: ○
B37: 2.2.G | C37: 2 | D37: リスクの特定と評価 (MAP) | E37: 2.2 | F37: リスクの分類と評価 | G37: Required | H37: 法的リスク（契約違反、規制違反等）の評価がされている | I37: ○ | K37: ○
B38: 2.2.H | C38: 2 | D38: リスクの特定と評価 (MAP) | E38: 2.2 | F38: リスクの分類と評価 | G38: Recommended | H38: レピュテーションリスクの評価がされている | I38: ○ | N38: ○
B39: 2.2.I | C39: 2 | D39: リスクの特定と評価 (MAP) | E39: 2.2 | F39: リスクの分類と評価 | G39: Recommended | H39: 業務依存リスク（過度な依存、スキル低下）の評価がされている | J39: ○ | N39: ○
B40: 2.2.J | C40: 2 | D40: リスクの特定と評価 (MAP) | E40: 2.2 | F40: リスクの分類と評価 | G40: Option | H40: 環境負荷・サステナビリティの考慮がされている | I40: ○ | K40: ○
...

Sheet サマリー
A1: チェック結果 全体サマリー
A2: ステータス | B2: 件数 | C2: 割合
A3: 対応済 | B3: =COUNTIF('チェックリスト'!$A$4:$A$123,"対応済") | C3: =B3/120
A4: 一部対応 | B4: =COUNTIF('チェックリスト'!$A$4:$A$123,"一部対応") | C4: =B4/120
A5: 未対応 | B5: =COUNTIF('チェックリスト'!$A$4:$A$123,"未対応") | C5: =B5/120
A6: 該当なし | B6: =COUNTIF('チェックリスト'!$A$4:$A$123,"該当なし") | C6: =B6/120
A7: 未記入 | B7: =COUNTBLANK('チェックリスト'!$A$4:$A$123) | C7: =B7/120
A8: 合計 | B8: 120
A10: 準拠レベル別 チェック結果
A11: レベル | B11: 項目数 | C11: 対応済 | D11: 一部対応 | E11: 未対応 | F11: 該当なし | G11: 未記入 | H11: 対応率
A12: Required | B12: =COUNTIF('チェックリスト'!$G$4:$G$123,"Required") | C12: =COUNTIFS('チェックリスト'!$G$4:$G$123,"Required",'チェックリスト'!$A$4:$A$123,"対応済") | D12: =COUNTIFS('チェックリスト'!$G$4:$G$123,"Required",'チェックリスト'!$A$4:$A$123,"一部対応") | E12: =COUNTIFS('チェックリスト'!$G$4:$G$123,"Required",'チェックリスト'!$A$4:$A$123,"未対応") | F12: =COUNTIFS('チェックリスト'!$G$4:$G$123,"Required",'チェックリスト'!$A$4:$A$123,"該当なし") | G12: =B12-SUM(C12:F12) | H12: =IFERROR(C12/B12,0)
A13: Recommended | B13: =COUNTIF('チェックリスト'!$G$4:$G$123,"Recommended") | C13: =COUNTIFS('チェックリスト'!$G$4:$G$123,"Recommended",'チェックリスト'!$A$4:$A$123,"対応済") | D13: =COUNTIFS('チェックリスト'!$G$4:$G$123,"Recommended",'チェックリスト'!$A$4:$A$123,"一部対応") | E13: =COUNTIFS('チェックリスト'!$G$4:$G$123,"Recommended",'チェックリスト'!$A$4:$A$123,"未対応") | F13: =COUNTIFS('チェックリスト'!$G$4:$G$123,"Recommended",'チェックリスト'!$A$4:$A$123,"該当なし") | G13: =B13-SUM(C13:F13) | H13: =IFERROR(C13/B13,0)
A14: Option | B14: =COUNTIF('チェックリスト'!$G$4:$G$123,"Option") | C14: =COUNTIFS('チェックリスト'!$G$4:$G$123,"Option",'チェックリスト'!$A$4:$A$123,"対応済") | D14: =COUNTIFS('チェックリスト'!$G$4:$G$123,"Option",'チェックリスト'!$A$4:$A$123,"一部対応") | E14: =COUNTIFS('チェックリスト'!$G$4:$G$123,"Option",'チェックリスト'!$A$4:$A$123,"未対応") | F14: =COUNTIFS('チェックリスト'!$G$4:$G$123,"Option",'チェックリスト'!$A$4:$A$123,"該当なし") | G14: =B14-SUM(C14:F14) | H14: =IFERROR(C14/B14,0)
A16: 章別 チェック結果
A17: 章 | B17: 項目数 | C17: 対応済 | D17: 一部対応 | E17: 未対応 | F17: 該当なし | G17: 未記入 | H17: 対応率 | I17: 必須対応率
A18: 1. ガバナンス体制 (GOVERN) | B18: =COUNTIF('チェックリスト'!$C$4:$C$123,1) | C18: =COUNTIFS('チェックリスト'!$C$4:$C$123,1,'チェックリスト'!$A$4:$A$123,"対応済") | D18: =COUNTIFS('チェックリスト'!$C$4:$C$123,1,'チェックリスト'!$A$4:$A$123,"一部対応") | E18: =COUNTIFS('チェックリスト'!$C$4:$C$123,1,'チェックリスト'!$A$4:$A$123,"未対応") | F18: =COUNTIFS('チェックリスト'!$C$4:$C$123,1,'チェックリスト'!$A$4:$A$123,"該当なし") | G18: =B18-SUM(C18:F18) | H18: =IFERROR(C18/B18,0) | I18: =IFERROR(COUNTIFS('チェックリスト'!$C$4:$C$123,1,'チェックリスト'!$G$4:$G$123,"Required",'チェックリスト'!$A$4:$A$123,"対応済")/COUNTIFS('チェックリスト'!$C$4:$C$123,1,'チェックリスト'!$G$4:$G$123,"Required"),0)
A19: 2. リスクの特定と評価 (MAP) | B19: =COUNTIF('チェックリスト'!$C$4:$C$123,2) | C19: =COUNTIFS('チェックリスト'!$C$4:$C$123,2,'チェックリスト'!$A$4:$A$123,"対応済") | D19: =COUNTIFS('チェックリスト'!$C$4:$C$123,2,'チェックリスト'!$A$4:$A$123,"一部対応") | E19: =COUNTIFS('チェックリスト'!$C$4:$C$123,2,'チェックリスト'!$A$4:$A$123,"未対応") | F19: =COUNTIFS('チェックリスト'!$C$4:$C$123,2,'チェックリスト'!$A$4:$A$123,"該当なし") | G19: =B19-SUM(C19:F19) | H19: =IFERROR(C19/B19,0) | I19: =IFERROR(COUNTIFS('チェックリスト'!$C$4:$C$123,2,'チェックリスト'!$G$4:$G$123,"Required",'チェックリスト'!$A$4:$A$123,"対応済")/COUNTIFS('チェックリスト'!$C$4:$C$123,2,'チェックリスト'!$G$4:$G$123,"Required"),0)
A20: 3. 入力データの管理 | B20: =COUNTIF('チェックリスト'!$C$4:$C$123,3) | C20: =COUNTIFS('チェックリスト'!$C$4:$C$123,3,'チェックリスト'!$A$4:$A$123,"対応済") | D20: =COUNTIFS('チェックリスト'!$C$4:$C$123,3,'チェックリスト'!$A$4:$A$123,"一部対応") | E20: =COUNTIFS('チェックリスト'!$C$4:$C$123,3,'チェックリスト'!$A$4:$A$123,"未対応") | F20: =COUNTIFS('チェックリスト'!$C$4:$C$123,3,'チェックリスト'!$A$4:$A$123,"該当なし") | G20: =B20-SUM(C20:F20) | H20: =IFERROR(C20/B20,0) | I20: =IFERROR(COUNTIFS('チェックリスト'!$C$4:$C$123,3,'チェックリスト'!$G$4:$G$123,"Required",'チェックリスト'!$A$4:$A$123,"対応済")/COUNTIFS('チェックリスト'!$C$4:$C$123,3,'チェックリスト'!$G$4:$G$123,"Required"),0)
A21: 4. 出力の管理と利用 | B21: =COUNTIF('チェックリスト'!$C$4:$C$123,4) | C21: =COUNTIFS('チェックリスト'!$C$4:$C$123,4,'チェックリスト'!$A$4:$A$123,"対応済") | D21: =COUNTIFS('チェックリスト'!$C$4:$C$123,4,'チェックリスト'!$A$4:$A$123,"一部対応") | E21: =COUNTIFS('チェックリスト'!$C$4:$C$123,4,'チェックリスト'!$A$4:$A$123,"未対応") | F21: =COUNTIFS('チェックリスト'!$C$4:$C$123,4,'チェックリスト'!$A$4:$A$123,"該当なし") | G21: =B21-SUM(C21:F21) | H21: =IFERROR(C21/B21,0) | I21: =IFERROR(COUNTIFS('チェックリスト'!$C$4:$C$123,4,'チェックリスト'!$G$4:$G$123,"Required",'チェックリスト'!$A$4:$A$123,"対応済")/COUNTIFS('チェックリスト'!$C$4:$C$123,4,'チェックリスト'!$G$4:$G$123,"Required"),0)
A22: 5. 信頼性の確保 (Trustworthiness) | B22: =COUNTIF('チェックリスト'!$C$4:$C$123,5) | C22: =COUNTIFS('チェックリスト'!$C$4:$C$123,5,'チェックリスト'!$A$4:$A$123,"対応済") | D22: =COUNTIFS('チェックリスト'!$C$4:$C$123,5,'チェックリスト'!$A$4:$A$123,"一部対応") | E22: =COUNTIFS('チェックリスト'!$C$4:$C$123,5,'チェックリスト'!$A$4:$A$123,"未対応") | F22: =COUNTIFS('チェックリスト'!$C$4:$C$123,5,'チェックリスト'!$A$4:$A$123,"該当なし") | G22: =B22-SUM(C22:F22) | H22: =IFERROR(C22/B22,0) | I22: =IFERROR(COUNTIFS('チェックリスト'!$C$4:$C$123,5,'チェックリスト'!$G$4:$G$123,"Required",'チェックリスト'!$A$4:$A$123,"対応済")/COUNTIFS('チェックリスト'!$C$4:$C$123,5,'チェックリスト'!$G$4:$G$123,"Required"),0)
A23: 6. インシデント対応 | B23: =COUNTIF('チェックリスト'!$C$4:$C$123,6) | C23: =COUNTIFS('チェックリスト'!$C$4:$C$123,6,'チェックリスト'!$A$4:$A$123,"対応済") | D23: =COUNTIFS('チェックリスト'!$C$4:$C$123,6,'チェックリスト'!$A$4:$A$123,"一部対応") | E23: =COUNTIFS('チェックリスト'!$C$4:$C$123,6,'チェックリスト'!$A$4:$A$123,"未対応") | F23: =COUNTIFS('チェックリスト'!$C$4:$C$123,6,'チェックリスト'!$A$4:$A$123,"該当なし") | G23: =B23-SUM(C23:F23) | H23: =IFERROR(C23/B23,0) | I23: =IFERROR(COUNTIFS('チェックリスト'!$C$4:$C$123,6,'チェックリスト'!$G$4:$G$123,"Required",'チェックリスト'!$A$4:$A$123,"対応済")/COUNTIFS('チェックリスト'!$C$4:$C$123,6,'チェックリスト'!$G$4:$G$123,"Required"),0)
A24: 7. ガイドラインとしての完成度 | B24: =COUNTIF('チェックリスト'!$C$4:$C$123,7) | C24: =COUNTIFS('チェックリスト'!$C$4:$C$123,7,'チェックリスト'!$A$4:$A$123,"対応済") | D24: =COUNTIFS('チェックリスト'!$C$4:$C$123,7,'チェックリスト'!$A$4:$A$123,"一部対応") | E24: =COUNTIFS('チェックリスト'!$C$4:$C$123,7,'チェックリスト'!$A$4:$A$123,"未対応") | F24: =COUNTIFS('チェックリスト'!$C$4:$C$123,7,'チェックリスト'!$A$4:$A$123,"該当なし") | G24: =B24-SUM(C24:F24) | H24: =IFERROR(C24/B24,0) | I24: =IFERROR(COUNTIFS('チェックリスト'!$C$4:$C$123,7,'チェックリスト'!$G$4:$G$123,"Required",'チェックリスト'!$A$4:$A$123,"対応済")/COUNTIFS('チェックリスト'!$C$4:$C$123,7,'チェックリスト'!$G$4:$G$123,"Required"),0)
A26: チェック結果の入力方法
A28: チェック結果の選択基準:
A29: 対応済: ガイドラインに該当する内容が記載されている
A30: 一部対応: 内容は含まれているが不十分、または表現が曖昧
A31: 未対応: ガイドラインに該当する記載がない
A32: 該当なし: 自組織の状況に照らして対応不要と判断した項目
A34: 推奨する進め方:
A35: 1. まず「Required」項目だけをフィルタで表示し、すべてチェックする
A36: 2. 次に「Recommended」項目を確認する
A37: 3. 最後に「Option」項目を組織の状況に応じて検討する
A38: 4.「該当なし」とした項目は、備考欄にその理由を記入する
